2022-06-23 02:25:10,389 INFO    MainThread:535241 [wandb_setup.py:_flush():76] Loading settings from /home/adriansegura/.config/wandb/settings
2022-06-23 02:25:10,389 INFO    MainThread:535241 [wandb_setup.py:_flush():76] Loading settings from /home/adriansegura/Desktop/RUG/CattleNet/convnext/wandb/settings
2022-06-23 02:25:10,389 INFO    MainThread:535241 [wandb_setup.py:_flush():76] Loading settings from environment variables: {}
2022-06-23 02:25:10,389 INFO    MainThread:535241 [wandb_setup.py:_flush():76] Inferring run settings from compute environment: {'program_relpath': 'convnext/setup.py', 'program': '/home/adriansegura/Desktop/RUG/CattleNet/convnext/setup.py'}
2022-06-23 02:25:10,389 INFO    MainThread:535241 [wandb_init.py:_log_setup():428] Logging user logs to /home/adriansegura/Desktop/RUG/CattleNet/convnext/wandb/run-20220623_022510-1j9gv6n1/logs/debug.log
2022-06-23 02:25:10,389 INFO    MainThread:535241 [wandb_init.py:_log_setup():429] Logging internal logs to /home/adriansegura/Desktop/RUG/CattleNet/convnext/wandb/run-20220623_022510-1j9gv6n1/logs/debug-internal.log
2022-06-23 02:25:10,389 INFO    MainThread:535241 [wandb_init.py:init():462] calling init triggers
2022-06-23 02:25:10,389 INFO    MainThread:535241 [wandb_init.py:init():465] wandb.init called with sweep_config: {}
config: {}
2022-06-23 02:25:10,389 INFO    MainThread:535241 [wandb_init.py:init():515] starting backend
2022-06-23 02:25:10,389 INFO    MainThread:535241 [backend.py:_multiprocessing_setup():97] multiprocessing start_methods=fork,spawn,forkserver, using: spawn
2022-06-23 02:25:10,391 INFO    MainThread:535241 [backend.py:ensure_launched():217] starting backend process...
2022-06-23 02:25:10,418 INFO    MainThread:535241 [backend.py:ensure_launched():222] started backend process with pid: 544202
2022-06-23 02:25:10,419 INFO    MainThread:535241 [wandb_init.py:init():525] backend started and connected
2022-06-23 02:25:10,424 INFO    MainThread:535241 [wandb_init.py:init():596] updated telemetry
2022-06-23 02:25:10,497 INFO    MainThread:535241 [wandb_init.py:init():627] communicating run to backend with 30 second timeout
2022-06-23 02:25:11,390 INFO    MainThread:535241 [wandb_run.py:_on_init():1924] communicating current version
2022-06-23 02:25:11,537 INFO    MainThread:535241 [wandb_run.py:_on_init():1928] got version response upgrade_message: "wandb version 0.12.19 is available!  To upgrade, please run:\n $ pip install wandb --upgrade"

2022-06-23 02:25:11,537 INFO    MainThread:535241 [wandb_init.py:init():662] starting run threads in backend
2022-06-23 02:25:14,883 INFO    MainThread:535241 [wandb_run.py:_console_start():1898] atexit reg
2022-06-23 02:25:14,884 INFO    MainThread:535241 [wandb_run.py:_redirect():1771] redirect: SettingsConsole.REDIRECT
2022-06-23 02:25:14,884 INFO    MainThread:535241 [wandb_run.py:_redirect():1776] Redirecting console.
2022-06-23 02:25:14,884 INFO    MainThread:535241 [wandb_run.py:_redirect():1832] Redirects installed.
2022-06-23 02:25:14,884 INFO    MainThread:535241 [wandb_init.py:init():688] run started, returning control to user process
2022-06-23 02:52:18,798 INFO    MainThread:535241 [wandb_run.py:_atexit_cleanup():1867] got exitcode: 1
2022-06-23 02:52:18,799 INFO    MainThread:535241 [wandb_run.py:_restore():1839] restore
2022-06-23 02:52:21,509 INFO    MainThread:535241 [wandb_run.py:_restore():1839] restore
2022-06-23 02:52:23,646 ERROR   MainThread:535241 [wandb_run.py:_atexit_cleanup():1888] Problem finishing run
Traceback (most recent call last):
  File "/home/adriansegura/anaconda3/lib/python3.9/site-packages/wandb/sdk/wandb_run.py", line 1876, in _atexit_cleanup
    self._on_finish()
  File "/home/adriansegura/anaconda3/lib/python3.9/site-packages/wandb/sdk/wandb_run.py", line 1987, in _on_finish
    self._footer_exit_status_info(
  File "/home/adriansegura/anaconda3/lib/python3.9/site-packages/wandb/sdk/wandb_run.py", line 2901, in _footer_exit_status_info
    printer.display(f'{" ".join(info)}')
  File "/home/adriansegura/anaconda3/lib/python3.9/site-packages/wandb/sdk/lib/printer.py", line 35, in display
    self._display(text, status=status)
  File "/home/adriansegura/anaconda3/lib/python3.9/site-packages/wandb/sdk/lib/printer.py", line 90, in _display
    wandb.termlog(text)
  File "/home/adriansegura/anaconda3/lib/python3.9/site-packages/wandb/errors/term.py", line 40, in termlog
    _log(
  File "/home/adriansegura/anaconda3/lib/python3.9/site-packages/wandb/errors/term.py", line 96, in _log
    click.echo(line, file=sys.stderr, nl=newline)
  File "/home/adriansegura/anaconda3/lib/python3.9/site-packages/click/utils.py", line 298, in echo
    file.write(out)  # type: ignore
OSError: [Errno 28] No space left on device
